1.异常

1.异常

是指在程序的运行过程中所发生的不正常的事件，它会中断正在运行的程序

2.异常处理

Java编程语言使用异常处理机制为程序提供了错误处理的能力

3.如何进行异常处理

Java的异常处理是通过5个关键字来实现的：try、catch、 finally、throw、throws



2.try-catch-finally

1.语法:

```javascript
try {
	//可能出现异常代码
} catch (异常类型 变量名) {
	//处理异常
} finally {
    //最终执行的代码
}
```



```javascript
try {
	System.out.println(1/0);
} catch (Exception e) {
	System.out.println("发生异常");
}
```



2.try-catch三种情况

(1)没有发生异常

执行try中的语句，不执行catch中的语句，继续往下执行

```javascript
try {
	System.out.println(1/1);
} catch (Exception e) {
    //不执行
	System.out.println("发生异常");
}
//继续往下执行
System.out.println("感谢使用本程序！");
```

(2)发生异常，被catch捕获

发生异常后执行catch中的语句，继续往下执行

```javascript
try {
    System.out.println("感谢使用本程序！");
	System.out.println(1/1);//进入catch
    System.out.println("感谢使用本程序！");
} catch (Exception e) {
    //执行
	System.out.println("发生异常");
}
//继续往下执行
System.out.println("感谢使用本程序！");
```

(3)发生异常，与catch中的类型不匹配

抛出异常，程序中断

```javascript
try {
	System.out.println(1/1);//抛出异常，程序中断
} catch (InputMismatchException e) {
    //执行
	System.out.println("发生异常");
}
System.out.println("感谢使用本程序！");
```



3.多个catch的排序

先子类后父类，按顺序匹配

只catch第一个符合的一场

```javascript
try {
	Scanner in = new Scanner(System.in);
	System.out.print("请输入被除数:");
	int num1 = in.nextInt();
	System.out.print("请输入除数:");
	int num2 = in.nextInt();
	System.out.println(num1 + "/" + num2 + "=" + num1 / num2);
	System.out.println("感谢使用本程序！");
} catch (ArithmeticException e) {
	System.out.println("出现算术错误异常");
	e.printStackTrace();
} catch (InputMismatchException e) {
	System.out.println("出现输入类型错误异常");
	e.printStackTrace();
} catch (Exception e) {
	System.out.println("出现异常");
	e.printStackTrace();
}
```



4.printStackTrace()和getMessage()

(1)printStackTrace()

输出异常的堆栈信息



从下往上溯源，一般看自己代码的最上行

```javascript
java.util.InputMismatchException
	at java.util.Scanner.throwFor(Scanner.java:909)
	at java.util.Scanner.next(Scanner.java:1530)
	at java.util.Scanner.nextInt(Scanner.java:2160)
	at java.util.Scanner.nextInt(Scanner.java:2119)
	at chap2_7.t1.D2.main(D2.java:12)
```



(2)getMessage()

返回异常信息描述字符串，

是printStackTrace()输出信息的一部分



有异常的没有

 / by zero即为异常信息

```javascript
java.lang.ArithmeticException: / by zero
	at chap2_7.t1.D2.main(D2.java:15)
```



5.finally

(1)无论有无异常，都将执行finally内容

```javascript
try {
	System.out.println(1/1);
} catch (ArithmeticException e) {
	System.out.println("发生异常:"+e);
}finally{
	System.out.println("finally执行内容");
}
```

(2)即使在try或catch中return，也会执行finally的内容

但是若return了变量，即使finally中又对变量进行操作，最终return的是try或catch中的值(JVM会创建变量暂存return的值)，除非finally中也进行return

```javascript
try {
	System.out.println(a / 1);
	return;
} catch (ArithmeticException e) {
	System.out.println("发生异常:" + e);
	return;
	
} finally {
	System.out.println("finally执行内容");
}
```

(3)唯一finally不执行的情况，System.exit();

```javascript
try {
	System.out.println(1 / 1);
	System.exit(0);
} catch (ArithmeticException e) {
	System.out.println("发生异常:" + e);
	
} finally {
	System.out.println("finally执行内容");
}
```



6.常见异常类型

| 异常类型 | 说明 |
| - | - |
| Exception  | 异常层次结构的父类 |
| ArithmeticException | 算术错误情形，如以零作除数 |
| ArrayIndexOutOfBoundsException | 数组下标越界 |
| NullPointerException | 尝试访问 null 对象成员 |
| ClassNotFoundException | 不能加载所需的类 |
| IllegalArgumentException | 方法接收到非法参数 |
| ClassCastException | 对象强制类型转换出错 |
| NumberFormatException | 数字格式转换异常，如把"abc"转换成数字 |




3.throw,throws

throw抛出异常，throws声明可能的异常

主动throw异常(checked),必须throws,必须处理

```javascript
public static void err() throws Exception{
	throw new Exception();
}
```

throws可能的输入异常,throws的异常为checked,必须处理

```javascript
public static void err() throws Exception{
	Scanner in = new Scanner(System.in);
    int num1 = in.nextInt();
}
```

RuntimeException,可以不throws，throws了也可以不处理

```javascript
public static void err(){
	throw new RuntimeException();
}
```



4.自定义异常

继承Exception、Throwable等

```javascript
public class MyException extends Exception{
	public MyException(){
	}
	
	public MyException(String message){
		super(message);
	}
}
```



```javascript
public class Test {

	//抛出MyException
	public static void func() throws MyException{
		throw new MyException("自定义错误");
	}
	
	public static void main(String[] args) {
		//捕获MyException
		try {
			func();
		} catch (Exception e) {
			e.printStackTrace();
		}
	}
}
```

