2.try-catch-finally

1.语法:

```javascript
try {
	//可能出现异常代码
} catch (异常类型 变量名) {
	//处理异常
} finally {
    //最终执行的代码
}
```



```javascript
try {
	System.out.println(1/0);
} catch (Exception e) {
	System.out.println("发生异常");
}
```



2.try-catch三种情况

(1)没有发生异常

执行try中的语句，不执行catch中的语句，继续往下执行

```javascript
try {
	System.out.println(1/1);
} catch (Exception e) {
    //不执行
	System.out.println("发生异常");
}
//继续往下执行
System.out.println("感谢使用本程序！");
```

(2)发生异常，被catch捕获

发生异常后执行catch中的语句，继续往下执行

```javascript
try {
    System.out.println("感谢使用本程序！");
	System.out.println(1/1);//进入catch
    System.out.println("感谢使用本程序！");
} catch (Exception e) {
    //执行
	System.out.println("发生异常");
}
//继续往下执行
System.out.println("感谢使用本程序！");
```

(3)发生异常，与catch中的类型不匹配

抛出异常，程序中断

```javascript
try {
	System.out.println(1/1);//抛出异常，程序中断
} catch (InputMismatchException e) {
    //执行
	System.out.println("发生异常");
}
System.out.println("感谢使用本程序！");
```



3.多个catch的排序

先子类后父类，按顺序匹配

只catch第一个符合的一场

```javascript
try {
	Scanner in = new Scanner(System.in);
	System.out.print("请输入被除数:");
	int num1 = in.nextInt();
	System.out.print("请输入除数:");
	int num2 = in.nextInt();
	System.out.println(num1 + "/" + num2 + "=" + num1 / num2);
	System.out.println("感谢使用本程序！");
} catch (ArithmeticException e) {
	System.out.println("出现算术错误异常");
	e.printStackTrace();
} catch (InputMismatchException e) {
	System.out.println("出现输入类型错误异常");
	e.printStackTrace();
} catch (Exception e) {
	System.out.println("出现异常");
	e.printStackTrace();
}
```



4.printStackTrace()和getMessage()

(1)printStackTrace()

输出异常的堆栈信息



从下往上溯源，一般看自己代码的最上行

```javascript
java.util.InputMismatchException
	at java.util.Scanner.throwFor(Scanner.java:909)
	at java.util.Scanner.next(Scanner.java:1530)
	at java.util.Scanner.nextInt(Scanner.java:2160)
	at java.util.Scanner.nextInt(Scanner.java:2119)
	at chap2_7.t1.D2.main(D2.java:12)
```



(2)getMessage()

返回异常信息描述字符串，

是printStackTrace()输出信息的一部分



有异常的没有

 / by zero即为异常信息

```javascript
java.lang.ArithmeticException: / by zero
	at chap2_7.t1.D2.main(D2.java:15)
```



5.finally

(1)无论有无异常，都将执行finally内容

```javascript
try {
	System.out.println(1/1);
} catch (ArithmeticException e) {
	System.out.println("发生异常:"+e);
}finally{
	System.out.println("finally执行内容");
}
```

(2)即使在try或catch中return，也会执行finally的内容

若try或catch中return了变量，finally中又对变量进行操作，最终return的还是是try或catch中的值(JVM会创建变量暂存return的值，但只是变量，若是变量指向的对象被修改，则修改有效)，除非finally中也进行return

```javascript
try {
	System.out.println(a / 1);
	return;
} catch (ArithmeticException e) {
	System.out.println("发生异常:" + e);
	return;
	
} finally {
	System.out.println("finally执行内容");
}
```

(3)唯一finally不执行的情况，System.exit();

```javascript
try {
	System.out.println(1 / 1);
	System.exit(0);
} catch (ArithmeticException e) {
	System.out.println("发生异常:" + e);
	
} finally {
	System.out.println("finally执行内容");
}
```



6.常见异常类型

https://docs.oracle.com/javase/tutorial/essential/exceptions/runtime.html

6.1 unchecked：Error 和 RuntimeException

| ArithmeticException | 算术错误情形，如以零作除数 |
| - | - |
| ArrayIndexOutOfBoundsException | 数组下标越界 |
| NullPointerException | 尝试访问 null 对象成员 |
| IllegalArgumentException | 方法接收到非法参数 |
| ClassCastException | 对象强制类型转换出错 |
| NumberFormatException | 数字格式转换异常，如把"abc"转换成数字 |
| InputMismatchException | 输入类型错误 |


IllegalArgumentException

StringIndexOutOfBoundsException



6.2 checked：Exception中除了RuntimeException

|   |   |
| - | - |
| ClassNotFoundException | 不能加载所需的类 |


IOException，子类FileNotFoundException

NoSuchFieldException

NoSuchMethodException

SQLException

InterruptedException

ServletException